Workbook

Sheet 红色系统输入黄色人工调整
A1: 品规属性 | G1: 盈利健康度因子 | H1: 预订活跃度因子 | I1: 库存健康因子 | J1: 品牌属性因子 | L1: 货源量合计
G2: 辖区标准差 | H2: 均值
G3: =_xlfn.STDEV.S(G5:G218) -> 64.160602
A4: 代码 | B4: 选品列表 | C4: 卷烟规格 | D4: 批发价 | E4: 平均市场价 | F4: 属性 | G4: 单条盈利 | H4: 预订率R | I4: 存销比T | J4: Bbase | K4: Bgoal | L4: 上半年箱数 | M4: 箱条数 | N4: 上半年条数
A5: 11010803 | B5: 1 | C5: 中南海(金8mg) | D5: 80 | E5: 80.346154 | F5: 紧俏烟 | G5: =E5-D5 -> 0.34615385 | H5: 0.09691982 | I5: 6.2467072 | J5: 1.5 | K5: 0.94438411 | L5: 904.4 | M5: 0.004 | N5: 226100
A6: 11010807 | C6: 中南海(硬酷爽风尚) | D6: 175 | E6: 171.21429 | F6: 新品卷烟 | G6: =E6-D6 -> -3.7857143 | H6: 0.76986268 | I6: 0.013564798 | J6: 2 | K6: 0.94230172 | L6: 165 | M6: 0.004 | N6: 41250
A7: 11010812 | C7: 中南海(5mg细支) | D7: 121.9 | E7: 117.61538 | F7: 均衡满足 | G7: =E7-D7 -> -4.2846154 | H7: 0.49369023 | I7: 2.2365056 | J7: 1 | K7: 0.9729328 | L7: 218 | M7: 0.004 | N7: 54500
A8: 11010813 | C8: 中南海(冰耀中支) | D8: 201.4 | E8: 201.30769 | F8: 新品卷烟 | G8: =E8-D8 -> -0.092307692 | H8: 0.85237159 | I8: 1.9849746 | J8: 2 | K8: 0.92108188 | L8: 444.7 | M8: 0.004 | N8: 111175
A9: 11010814 | C9: 中南海(冰耀细支) | D9: 225 | E9: 163.46154 | F9: 新品卷烟 | G9: =E9-D9 -> -61.538462 | H9: 0.75758977 | I9: 5.9302154 | J9: 2 | K9: 0.90477013 | L9: 75.8 | M9: 0.004 | N9: 18950
A10: 12010601 | B10: 1 | C10: 大前门(软) | D10: 53 | E10: 90.461538 | F10: 紧俏烟 | G10: =E10-D10 -> 37.461538 | H10: 0.65951483 | I10: 1.7935607 | J10: 1.5 | K10: 0.96253086 | L10: 5000 | M10: 0.004 | N10: 1250000
A11: 12011119 | B11: 1 | C11: 恒大(烟魁1949中支) | D11: 551.2 | E11: 517.69231 | F11: 均衡满足 | G11: =E11-D11 -> -33.507692 | H11: 0.7264392 | I11: 3.241802 | J11: 1 | K11: 0.90703674 | L11: 424.1 | M11: 0.004 | N11: 106025
A12: 13070202 | C12: 钻石(硬特醇) | D12: 44.5 | E12: 66.769231 | F12: 完全满足 | G12: =E12-D12 -> 22.269231 | H12: 0.24756883 | I12: 2.0356778 | J12: 0.9 | K12: 0.98189677 | L12: 6350 | M12: 0.004 | N12: 1587500
A13: 13070217 | C13: 钻石(荷花) | D13: 275.6 | E13: 301.38462 | F13: 均衡满足 | G13: =E13-D13 -> 25.784615 | H13: 0.15038369 | I13: 2.9873626 | J13: 1 | K13: 0.94222574 | L13: 6062 | M13: 0.004 | N13: 1515500
A14: 13070221 | C14: 钻石(细支荷花) | D14: 360.4 | E14: 354.92308 | F14: 均衡满足 | G14: =E14-D14 -> -5.4769231 | H14: 0.36049867 | I14: 2.700451 | J14: 1 | K14: 0.92772331 | L14: 682 | M14: 0.004 | N14: 170500
A15: 13070222 | C15: 钻石(软荷花) | D15: 339.2 | E15: 336.30769 | F15: 均衡满足 | G15: =E15-D15 -> -2.8923077 | H15: 0.44064117 | I15: 5.9215272 | J15: 1 | K15: 0.96173861 | L15: 1020 | M15: 0.004 | N15: 255000
A16: 13070224 | C16: 钻石(细支尚风) | D16: 114.5 | E16: 124.23077 | F16: 完全满足 | G16: =E16-D16 -> 9.7307692 | H16: 0.4364217 | I16: 9.31074 | J16: 0.9 | K16: 0.97285876 | L16: 254 | M16: 0.004 | N16: 63500
A17: 13070225 | C17: 钻石(玫瑰二代) | D17: 97 | E17: 106.61538 | F17: 完全满足 | G17: =E17-D17 -> 9.6153846 | H17: 0.25004996 | I17: 6.6166026 | J17: 0.9 | K17: 0.9571883 | L17: 112 | M17: 0.004 | N17: 28000
A18: 13070227 | C18: 钻石(荷花小雅90mm细支) | D18: 470 | E18: 456.34615 | F18: 新品卷烟 | G18: =E18-D18 -> -13.653846 | H18: 0.21256574 | I18: 2.6034055 | J18: 2 | K18: 0.92936447 | L18: 50 | M18: 0.004 | N18: 12500
A19: 15010203 | C19: 冬虫夏草(和润) | D19: 424 | E19: 369.10769 | F19: 完全满足 | G19: =E19-D19 -> -54.892308 | H19: 0.67372751 | I19: 8.444085 | J19: 0.9 | K19: 0.95079413 | L19: 69.7 | M19: 0.004 | N19: 17425
A20: 15010205 | C20: 冬虫夏草(双中支) | D20: 339.2 | E20: 309.69231 | F20: 完全满足 | G20: =E20-D20 -> -29.507692 | H20: 0.84906722 | I20: 1.5149341 | J20: 0.9 | K20: 0.96822487 | L20: 299.9 | M20: 0.004 | N20: 74975
A21: 15010207 | C21: 冬虫夏草(岁悦细支) | D21: 339.2 | E21: 274 | F21: 新品卷烟 | G21: =E21-D21 -> -65.2 | H21: 0.0028452388 | I21: 3.7846821 | J21: 2 | K21: 0.90902525 | L21: 18.8 | M21: 0.004 | N21: 4700
A22: 15010301 | C22: 云烟(硬苁蓉) | D22: 114.5 | E22: 106.61538 | F22: 完全满足 | G22: =E22-D22 -> -7.8846154 | H22: 0.60475173 | I22: 1.1212547 | J22: 0.9 | K22: 0.98973667 | L22: 654.5 | M22: 0.004 | N22: 163625
A23: 21020107 | C23: 人民大会堂(硬红细支) | D23: 139.92 | E23: 146.38462 | F23: 完全满足 | G23: =E23-D23 -> 6.4646154 | H23: 0.051836651 | I23: 0.35243024 | J23: 0.9 | K23: 0.99491267 | L23: 1179.6 | M23: 0.004 | N23: 294900
... A30: 22240215 | C30: 长白山(迎春中支) | D30: 97 | E30: 138.69231 | F30: 完全满足 | G30: =E30-D30 -> 41.692308 | H30: 0.058008963 | I30: 2.9539731 | J30: 0.9 | K30: 0.98107539 | L30: 1929 | M30: 0.004 | N30: 482250
A31: 22240217 | B31: 1 | C31: 长白山(蓝尚) | D31: 158 | E31: 159.69231 | F31: 完全满足 | G31: =E31-D31 -> 1.6923077 | H31: 0.56484074 | I31: 5.7014573 | J31: 0.9 | K31: 0.95290446 | L31: 5050 | M31: 0.004 | N31: 1262500
A32: 22240219 | C32: 长白山(心归细支) | D32: 225 | E32: 225.66667 | F32: 新品卷烟 | G32: =E32-D32 -> 0.66666667 | H32: 0.14578348 | I32: 1.7948638 | J32: 2 | K32: 0.96019498 | L32: 125 | M32: 0.004 | N32: 31250
A33: 23010303 | C33: 哈尔滨(老巴夺) | D33: 97 | E33: 119.46154 | F33: 完全满足 | G33: =E33-D33 -> 22.461538 | H33: 0.77777745 | I33: 0.63672776 | J33: 0.9 | K33: 0.98247933 | L33: 565 | M33: 0.004 | N33: 141250
A34: 23010402 | C34: 龙烟(老巴夺传呈） | D34: 175 | E34: 156.42308 | F34: 新品卷烟 | G34: =E34-D34 -> -18.576923 | H34: 0.6453893 | I34: 7.9643476 | J34: 2 | K34: 0.91577524 | L34: 114.7 | M34: 0.004 | N34: 28675
A35: 31010412 | C35: 红双喜(硬江山精品) | D35: 88 | E35: 106.38462 | F35: 紧俏烟 | G35: =E35-D35 -> 18.384615 | H35: 0.71025177 | I35: 2.9985384 | J35: 1.5 | K35: 0.96125271 | L35: 14500 | M35: 0.004 | N35: 3625000
A36: 31010413 | C36: 红双喜(硬江山珍品) | D36: 143.1 | E36: 129.53846 | F36: 完全满足 | G36: =E36-D36 -> -13.561538 | H36: 0.17249425 | I36: 1.5305374 | J36: 0.9 | K36: 0.95213346 | L36: 1900 | M36: 0.004 | N36: 475000
A37: 31010505 | C37: 牡丹(软) | D37: 121.9 | E37: 144.53846 | F37: 完全满足 | G37: =E37-D37 -> 22.638462 | H37: 0.90323326 | I37: 1.1579571 | J37: 0.9 | K37: 0.95771778 | L37: 3809 | M37: 0.004 | N37: 952250
A38: 31010509 | C38: 牡丹(蓝中支) | D38: 263 | E38: 274.53846 | F38: 均衡满足 | G38: =E38-D38 -> 11.538462 | H38: 0.38362901 | I38: 3.7265998 | J38: 1 | K38: 0.96315037 | L38: 300 | M38: 0.004 | N38: 75000
A39: 31010510 | C39: 牡丹(红中支) | D39: 175 | E39: 213.38462 | F39: 新品卷烟 | G39: =E39-D39 -> 38.384615 | H39: 0.96308093 | I39: 5.5538441 | J39: 2 | K39: 0.94802191 | L39: 836.9 | M39: 0.004 | N39: 209225
A40: 31010511 | C40: 牡丹(恒大天青细支) | D40: 225 | E40: 191.76923 | F40: 新品卷烟 | G40: =E40-D40 -> -33.230769 | H40: 0.61740101 | I40: 7.8634214 | J40: 2 | K40: 0.96919399 | L40: 629 | M40: 0.004 | N40: 157250
A41: 31010512 | C41: 牡丹(恒大蓝金中支) | D41: 225 | E41: 205.53846 | F41: 新品卷烟 | G41: =E41-D41 -> -19.461538 | H41: 0.80800012 | I41: 7.9740718 | J41: 2 | K41: 0.97422949 | L41: 690 | M41: 0.004 | N41: 172500
A42: 31010513 | C42: 牡丹(恒大硬中支) | D42: 201.4 | E42: 201.61538 | F42: 新品卷烟 | G42: =E42-D42 -> 0.21538462 | H42: 0.92524079 | I42: 7.4733008 | J42: 2 | K42: 0.91585433 | L42: 4404.3 | M42: 0.004 | N42: 1101075
A43: 31010514 | C43: 牡丹(蓝彩细支) | D43: 263 | E43: 250 | F43: 新品卷烟 | G43: =E43-D43 -> -13 | H43: 0.14563647 | I43: 5.4390503 | J43: 2 | K43: 0.93977663 | L43: 220 | M43: 0.004 | N43: 55000
... A46: 31010701 | C46: 中华(硬) | D46: 381.6 | E46: 352.07692 | F46: 完全满足 | G46: =E46-D46 -> -29.523077 | H46: 0.5719041 | I46: 5.7793984 | J46: 0.9 | K46: 0.91871289 | L46: 7500 | M46: 0.004 | N46: 1875000
A47: 31010702 | B47: 1 | C47: 中华(软) | D47: 583 | E47: 525 | F47: 完全满足 | G47: =E47-D47 -> -58 | H47: 0.33655878 | I47: 2.5447815 | J47: 0.9 | K47: 0.96531472 | L47: 2000 | M47: 0.004 | N47: 500000
A48: 31010711 | C48: 中华(全开式) | D48: 381.6 | E48: 365.15385 | F48: 均衡满足 | G48: =E48-D48 -> -16.446154 | H48: 0.54783206 | I48: 7.4590846 | J48: 1 | K48: 0.96950202 | L48: 194 | M48: 0.004 | N48: 48500
...

Sheet 所选品规列表
A1: 按需预订参数设定 | I1: 积分池情况
A2: 基准积分 | B2: 分值 | C2: 权重 | D2: 盈利健康度因子 | E2: 预订活跃度因子 | F2: 库存健康因子 | G2: 品牌属性因子 | I2: 选品预订积分 | J2: 选品销售积分 | K2: 总积分数
A3: 预订基准积分 | B3: 6 | C3: 预订权重指数 | D3: 3 | E3: 0.3 | F3: 0.3 | G3: 0.3 | I3: =红色系统输入黄色人工调整!#REF! -> #REF! | J3: =红色系统输入黄色人工调整!#REF! -> #REF! | K3: =红色系统输入黄色人工调整!#REF! -> #REF!
A4: 销售基准积分 | B4: 3 | C4: 销售权重指数 | D4: 3 | E4: =E3 -> 0.3 | F4: =F3 -> 0.3 | G4: =G3 -> 0.3
A5: 按需预订品规列表
A6: 编码 | B6: 名称 | C6: 批发价 | D6: 市场价 | E6: 预订积分 | F6: 销售积分 | G6: 积分数 | H6: 上半年箱数 | I6: 总预订积分数 | J6: 总消费积分数 | K6: 总积分数
A7: {=_xlfn._xlws.FILTER(红色系统输入黄色人工调整!A5:A218,红色系统输入黄色人工调整!B5:B218=1)} -> #NAME? | B7: {=_xlfn._xlws.FILTER(红色系统输入黄色人工调整!C5:C218,红色系统输入黄色人工调整!B5:B218=1)} -> #NAME? | C7: {=_xlfn._xlws.FILTER(红色系统输入黄色人工调整!D5:E218,红色系统输入黄色人工调整!B5:B218=1)} -> #NAME? | D7: #NAME? | E7: {=_xlfn._xlws.FILTER(红色系统输入黄色人工调整!#REF!,红色系统输入黄色人工调整!B5:B218=1)} -> #NAME? | F7: #NAME? | G7: =IF(E7="","",F7-E7) -> #NAME? | H7: {=_xlfn._xlws.FILTER(红色系统输入黄色人工调整!#REF!,红色系统输入黄色人工调整!B5:B218=1)} -> #NAME? | I7: {=_xlfn._xlws.FILTER(红色系统输入黄色人工调整!#REF!,红色系统输入黄色人工调整!B5:B218=1)} -> #NAME? | J7: #NAME? | K7: #NAME?
A8: #NAME? | B8: #NAME? | C8: #NAME? | D8: #NAME? | E8: #NAME? | F8: #NAME? | G8: =IF(E8="","",F8-E8) -> #NAME? | H8: #NAME? | I8: #NAME? | J8: #NAME? | K8: #NAME?
A9: #NAME? | B9: #NAME? | C9: #NAME? | D9: #NAME? | E9: #NAME? | F9: #NAME? | G9: =IF(E9="","",F9-E9) -> #NAME? | H9: #NAME? | I9: #NAME? | J9: #NAME? | K9: #NAME?
A10: #NAME? | B10: #NAME? | C10: #NAME? | D10: #NAME? | E10: #NAME? | F10: #NAME? | G10: =IF(E10="","",F10-E10) -> #NAME? | H10: #NAME? | I10: #NAME? | J10: #NAME? | K10: #NAME?
A11: #NAME? | B11: #NAME? | C11: #NAME? | D11: #NAME? | E11: #NAME? | F11: #NAME? | G11: =IF(E11="","",F11-E11) -> #NAME? | H11: #NAME? | I11: #NAME? | J11: #NAME? | K11: #NAME?
G12: =IF(E12="","",F12-E12)
G13: =IF(E13="","",F13-E13)
G14: =IF(E14="","",F14-E14)
G15: =IF(E15="","",F15-E15)
G16: =IF(E16="","",F16-E16)
G17: =IF(E17="","",F17-E17)
G18: =IF(E18="","",F18-E18)
G19: =IF(E19="","",F19-E19)
G20: =IF(E20="","",F20-E20)
G21: =IF(E21="","",F21-E21)
G22: =IF(E22="","",F22-E22)
G23: =IF(E23="","",F23-E23)
... G26: =IF(E26="","",F26-E26)
